2019-12-26 16:39:43.758 parsl.dataflow.dflow:83 [DEBUG]  Starting DataFlowKernel with config
Config(
    app_cache=True, 
    checkpoint_files=None, 
    checkpoint_mode=None, 
    checkpoint_period=None, 
    data_management_max_threads=10, 
    executors=[ThreadPoolExecutor(
        label='threads', 
        managed=True, 
        max_threads=2, 
        storage_access=None, 
        thread_name_prefix='', 
        working_dir=None
    )], 
    initialize_logging=True, 
    lazy_errors=True, 
    max_idletime=120.0, 
    monitoring=None, 
    retries=0, 
    run_dir='runinfo', 
    strategy='simple', 
    usage_tracking=False
)
2019-12-26 16:39:43.758 parsl.dataflow.dflow:84 [INFO]  Parsl version: 0.9.0
2019-12-26 16:39:43.758 parsl.dataflow.usage_tracking.usage:126 [DEBUG]  Tracking status: False
2019-12-26 16:39:43.758 parsl.dataflow.usage_tracking.usage:127 [DEBUG]  Testing mode   : False
2019-12-26 16:39:43.758 parsl.dataflow.dflow:110 [INFO]  Run id is: fdb8262c-28b4-4c69-97be-3f7ef74b82bf
2019-12-26 16:39:43.808 parsl.dataflow.memoization:52 [INFO]  App caching initialized
2019-12-26 16:39:43.809 parsl.dataflow.strategy:125 [DEBUG]  Scaling strategy: simple
2019-12-26 16:39:44.072 parsl.dataflow.dflow:484 [DEBUG]  Adding output dependencies
2019-12-26 16:39:44.072 parsl.dataflow.dflow:708 [INFO]  Task 0 submitted for App kmeans, waiting on tasks []
2019-12-26 16:39:44.072 parsl.dataflow.dflow:714 [DEBUG]  Task 0 set to pending state with AppFuture: <AppFuture super=<AppFuture at 0x7f54bf3707b8 state=pending>>
2019-12-26 16:39:44.073 parsl.dataflow.dflow:452 [INFO]  Task 0 launched on executor threads
2019-12-26 16:39:44.073 parsl.dataflow.dflow:484 [DEBUG]  Adding output dependencies
2019-12-26 16:39:44.073 parsl.dataflow.dflow:708 [INFO]  Task 1 submitted for App kmeans, waiting on tasks []
2019-12-26 16:39:44.073 parsl.dataflow.dflow:714 [DEBUG]  Task 1 set to pending state with AppFuture: <AppFuture super=<AppFuture at 0x7f54a9fbe400 state=pending>>
2019-12-26 16:39:44.073 parsl.dataflow.dflow:452 [INFO]  Task 1 launched on executor threads
2019-12-26 16:39:44.073 parsl.dataflow.dflow:484 [DEBUG]  Adding output dependencies
2019-12-26 16:39:44.073 parsl.dataflow.dflow:708 [INFO]  Task 2 submitted for App kmeans, waiting on tasks []
2019-12-26 16:39:44.074 parsl.dataflow.dflow:714 [DEBUG]  Task 2 set to pending state with AppFuture: <AppFuture super=<AppFuture at 0x7f54a9fbe6d8 state=pending>>
2019-12-26 16:39:44.074 parsl.dataflow.dflow:452 [INFO]  Task 2 launched on executor threads
2019-12-26 16:39:44.373 parsl.app.errors:158 [DEBUG]  Reraising exception of type <class 'KeyError'>
2019-12-26 16:39:44.374 parsl.app.errors:158 [DEBUG]  Reraising exception of type <class 'KeyError'>
2019-12-26 16:39:44.374 parsl.dataflow.dflow:257 [DEBUG]  Task 0 failed
2019-12-26 16:39:44.375 parsl.dataflow.dflow:257 [DEBUG]  Task 1 failed
2019-12-26 16:39:44.375 parsl.dataflow.dflow:279 [ERROR]  Task 0 failed after 0 retry attempts
Traceback (most recent call last):
  File "/home/amanda/.local/lib/python3.5/site-packages/parsl/dataflow/dflow.py", line 254, in handle_exec_update
    res.reraise()
  File "/home/amanda/.local/lib/python3.5/site-packages/parsl/app/errors.py", line 163, in reraise
    reraise(t, v, tb)
  File "/home/amanda/.local/lib/python3.5/site-packages/six.py", line 692, in reraise
    raise value.with_traceback(tb)
  File "/home/amanda/.local/lib/python3.5/site-packages/parsl/app/errors.py", line 172, in wrapper
    return func(*args, **kwargs)
  File "kmeansModelTraining.py", line 74, in kmeans
    y = df[clusterLabel].values
  File "/home/amanda/.local/lib/python3.5/site-packages/pandas/core/frame.py", line 1963, in __getitem__
    return self._getitem_array(key)
  File "/home/amanda/.local/lib/python3.5/site-packages/pandas/core/frame.py", line 2007, in _getitem_array
    indexer = self.ix._convert_to_indexer(key, axis=1)
  File "/home/amanda/.local/lib/python3.5/site-packages/pandas/core/indexing.py", line 1150, in _convert_to_indexer
    raise KeyError('%s not in index' % objarr[mask])
KeyError: "['QuadClass'] not in index"
2019-12-26 16:39:44.375 parsl.dataflow.dflow:279 [ERROR]  Task 1 failed after 0 retry attempts
Traceback (most recent call last):
  File "/home/amanda/.local/lib/python3.5/site-packages/parsl/dataflow/dflow.py", line 254, in handle_exec_update
    res.reraise()
  File "/home/amanda/.local/lib/python3.5/site-packages/parsl/app/errors.py", line 163, in reraise
    reraise(t, v, tb)
  File "/home/amanda/.local/lib/python3.5/site-packages/six.py", line 692, in reraise
    raise value.with_traceback(tb)
  File "/home/amanda/.local/lib/python3.5/site-packages/parsl/app/errors.py", line 172, in wrapper
    return func(*args, **kwargs)
  File "kmeansModelTraining.py", line 74, in kmeans
    y = df[clusterLabel].values
  File "/home/amanda/.local/lib/python3.5/site-packages/pandas/core/frame.py", line 1963, in __getitem__
    return self._getitem_array(key)
  File "/home/amanda/.local/lib/python3.5/site-packages/pandas/core/frame.py", line 2007, in _getitem_array
    indexer = self.ix._convert_to_indexer(key, axis=1)
  File "/home/amanda/.local/lib/python3.5/site-packages/pandas/core/indexing.py", line 1150, in _convert_to_indexer
    raise KeyError('%s not in index' % objarr[mask])
KeyError: "['QuadClass'] not in index"
2019-12-26 16:39:44.376 parsl.app.errors:158 [DEBUG]  Reraising exception of type <class 'KeyError'>
2019-12-26 16:39:44.376 parsl.app.errors:158 [DEBUG]  Reraising exception of type <class 'KeyError'>
2019-12-26 16:39:44.377 parsl.app.errors:158 [DEBUG]  Reraising exception of type <class 'KeyError'>
2019-12-26 16:39:44.378 parsl.dataflow.dflow:257 [DEBUG]  Task 2 failed
2019-12-26 16:39:44.378 parsl.dataflow.dflow:279 [ERROR]  Task 2 failed after 0 retry attempts
Traceback (most recent call last):
  File "/home/amanda/.local/lib/python3.5/site-packages/parsl/dataflow/dflow.py", line 254, in handle_exec_update
    res.reraise()
  File "/home/amanda/.local/lib/python3.5/site-packages/parsl/app/errors.py", line 163, in reraise
    reraise(t, v, tb)
  File "/home/amanda/.local/lib/python3.5/site-packages/six.py", line 692, in reraise
    raise value.with_traceback(tb)
  File "/home/amanda/.local/lib/python3.5/site-packages/parsl/app/errors.py", line 172, in wrapper
    return func(*args, **kwargs)
  File "kmeansModelTraining.py", line 74, in kmeans
    y = df[clusterLabel].values
  File "/home/amanda/.local/lib/python3.5/site-packages/pandas/core/frame.py", line 1963, in __getitem__
    return self._getitem_array(key)
  File "/home/amanda/.local/lib/python3.5/site-packages/pandas/core/frame.py", line 2007, in _getitem_array
    indexer = self.ix._convert_to_indexer(key, axis=1)
  File "/home/amanda/.local/lib/python3.5/site-packages/pandas/core/indexing.py", line 1150, in _convert_to_indexer
    raise KeyError('%s not in index' % objarr[mask])
KeyError: "['QuadClass'] not in index"
2019-12-26 16:39:44.378 parsl.app.errors:158 [DEBUG]  Reraising exception of type <class 'KeyError'>
2019-12-26 16:39:44.392 parsl.dataflow.dflow:864 [INFO]  DFK cleanup initiated
2019-12-26 16:39:44.392 parsl.dataflow.dflow:750 [INFO]  Summary of tasks in DFK:
2019-12-26 16:39:44.392 parsl.dataflow.dflow:781 [INFO]  Tasks in state States.failed: 0, 1, 2
2019-12-26 16:39:44.392 parsl.dataflow.dflow:788 [INFO]  End of summary
2019-12-26 16:39:44.393 parsl.dataflow.dflow:888 [INFO]  Terminating flow_control and strategy threads
2019-12-26 16:39:44.393 parsl.executors.threads:96 [DEBUG]  Done with executor shutdown
2019-12-26 16:39:44.393 parsl.executors.threads:96 [DEBUG]  Done with executor shutdown
2019-12-26 16:39:44.393 parsl.dataflow.dflow:920 [INFO]  DFK cleanup complete
